2020-07-06 09:47:03,559 ERROR: Exception on /checkIn [POST] [in c:\users\richa\onedrive\projects\azurecheckin\venv\lib\site-packages\flask\app.py:1891]
Traceback (most recent call last):
  File "c:\users\richa\onedrive\projects\azurecheckin\venv\lib\site-packages\sqlalchemy\engine\base.py", line 2276, in _wrap_pool_connect
    return fn()
  File "c:\users\richa\onedrive\projects\azurecheckin\venv\lib\site-packages\sqlalchemy\pool\base.py", line 363, in connect
    return _ConnectionFairy._checkout(self)
  File "c:\users\richa\onedrive\projects\azurecheckin\venv\lib\site-packages\sqlalchemy\pool\base.py", line 773, in _checkout
    fairy = _ConnectionRecord.checkout(pool)
  File "c:\users\richa\onedrive\projects\azurecheckin\venv\lib\site-packages\sqlalchemy\pool\base.py", line 492, in checkout
    rec = pool._do_get()
  File "c:\users\richa\onedrive\projects\azurecheckin\venv\lib\site-packages\sqlalchemy\pool\impl.py", line 139, in _do_get
    self._dec_overflow()
  File "c:\users\richa\onedrive\projects\azurecheckin\venv\lib\site-packages\sqlalchemy\util\langhelpers.py", line 68, in __exit__
    compat.reraise(exc_type, exc_value, exc_tb)
  File "c:\users\richa\onedrive\projects\azurecheckin\venv\lib\site-packages\sqlalchemy\util\compat.py", line 153, in reraise
    raise value
  File "c:\users\richa\onedrive\projects\azurecheckin\venv\lib\site-packages\sqlalchemy\pool\impl.py", line 136, in _do_get
    return self._create_connection()
  File "c:\users\richa\onedrive\projects\azurecheckin\venv\lib\site-packages\sqlalchemy\pool\base.py", line 308, in _create_connection
    return _ConnectionRecord(self)
  File "c:\users\richa\onedrive\projects\azurecheckin\venv\lib\site-packages\sqlalchemy\pool\base.py", line 437, in __init__
    self.__connect(first_connect_check=True)
  File "c:\users\richa\onedrive\projects\azurecheckin\venv\lib\site-packages\sqlalchemy\pool\base.py", line 652, in __connect
    connection = pool._invoke_creator(self)
  File "c:\users\richa\onedrive\projects\azurecheckin\venv\lib\site-packages\sqlalchemy\engine\strategies.py", line 114, in connect
    return dialect.connect(*cargs, **cparams)
  File "c:\users\richa\onedrive\projects\azurecheckin\venv\lib\site-packages\sqlalchemy\engine\default.py", line 489, in connect
    return self.dbapi.connect(*cargs, **cparams)
pyodbc.ProgrammingError: ('42000', "[42000] [Microsoft][ODBC Driver 17 for SQL Server][SQL Server]Cannot open server 'vwcweb' requested by the login. Client with IP address '73.21.244.163' is not allowed to access the server.  To enable access, use the Windows Azure Management Portal or run sp_set_firewall_rule on the master database to create a firewall rule for this IP address or address range.  It may take up to five minutes for this change to take effect. (40615) (SQLDriverConnect); [42000] [Microsoft][ODBC Driver 17 for SQL Server][SQL Server]Cannot open server 'vwcweb' requested by the login. Client with IP address '73.21.244.163' is not allowed to access the server.  To enable access, use the Windows Azure Management Portal or run sp_set_firewall_rule on the master database to create a firewall rule for this IP address or address range.  It may take up to five minutes for this change to take effect. (40615)")

The above exception was the direct cause of the following exception:

Traceback (most recent call last):
  File "c:\users\richa\onedrive\projects\azurecheckin\venv\lib\site-packages\flask\app.py", line 2446, in wsgi_app
    response = self.full_dispatch_request()
  File "c:\users\richa\onedrive\projects\azurecheckin\venv\lib\site-packages\flask\app.py", line 1951, in full_dispatch_request
    rv = self.handle_user_exception(e)
  File "c:\users\richa\onedrive\projects\azurecheckin\venv\lib\site-packages\flask\app.py", line 1820, in handle_user_exception
    reraise(exc_type, exc_value, tb)
  File "c:\users\richa\onedrive\projects\azurecheckin\venv\lib\site-packages\flask\_compat.py", line 39, in reraise
    raise value
  File "c:\users\richa\onedrive\projects\azurecheckin\venv\lib\site-packages\flask\app.py", line 1949, in full_dispatch_request
    rv = self.dispatch_request()
  File "c:\users\richa\onedrive\projects\azurecheckin\venv\lib\site-packages\flask\app.py", line 1935, in dispatch_request
    return self.view_functions[rule.endpoint](**req.view_args)
  File "C:\Users\richa\OneDrive\Projects\AzureCheckIn\app\routes.py", line 34, in checkIn
    member = db.engine.execute(sqlSelect)
  File "c:\users\richa\onedrive\projects\azurecheckin\venv\lib\site-packages\sqlalchemy\engine\base.py", line 2181, in execute
    connection = self._contextual_connect(close_with_result=True)
  File "c:\users\richa\onedrive\projects\azurecheckin\venv\lib\site-packages\sqlalchemy\engine\base.py", line 2242, in _contextual_connect
    self._wrap_pool_connect(self.pool.connect, None),
  File "c:\users\richa\onedrive\projects\azurecheckin\venv\lib\site-packages\sqlalchemy\engine\base.py", line 2280, in _wrap_pool_connect
    e, dialect, self
  File "c:\users\richa\onedrive\projects\azurecheckin\venv\lib\site-packages\sqlalchemy\engine\base.py", line 1547, in _handle_dbapi_exception_noconnection
    util.raise_from_cause(sqlalchemy_exception, exc_info)
  File "c:\users\richa\onedrive\projects\azurecheckin\venv\lib\site-packages\sqlalchemy\util\compat.py", line 398, in raise_from_cause
    reraise(type(exception), exception, tb=exc_tb, cause=cause)
  File "c:\users\richa\onedrive\projects\azurecheckin\venv\lib\site-packages\sqlalchemy\util\compat.py", line 152, in reraise
    raise value.with_traceback(tb)
  File "c:\users\richa\onedrive\projects\azurecheckin\venv\lib\site-packages\sqlalchemy\engine\base.py", line 2276, in _wrap_pool_connect
    return fn()
  File "c:\users\richa\onedrive\projects\azurecheckin\venv\lib\site-packages\sqlalchemy\pool\base.py", line 363, in connect
    return _ConnectionFairy._checkout(self)
  File "c:\users\richa\onedrive\projects\azurecheckin\venv\lib\site-packages\sqlalchemy\pool\base.py", line 773, in _checkout
    fairy = _ConnectionRecord.checkout(pool)
  File "c:\users\richa\onedrive\projects\azurecheckin\venv\lib\site-packages\sqlalchemy\pool\base.py", line 492, in checkout
    rec = pool._do_get()
  File "c:\users\richa\onedrive\projects\azurecheckin\venv\lib\site-packages\sqlalchemy\pool\impl.py", line 139, in _do_get
    self._dec_overflow()
  File "c:\users\richa\onedrive\projects\azurecheckin\venv\lib\site-packages\sqlalchemy\util\langhelpers.py", line 68, in __exit__
    compat.reraise(exc_type, exc_value, exc_tb)
  File "c:\users\richa\onedrive\projects\azurecheckin\venv\lib\site-packages\sqlalchemy\util\compat.py", line 153, in reraise
    raise value
  File "c:\users\richa\onedrive\projects\azurecheckin\venv\lib\site-packages\sqlalchemy\pool\impl.py", line 136, in _do_get
    return self._create_connection()
  File "c:\users\richa\onedrive\projects\azurecheckin\venv\lib\site-packages\sqlalchemy\pool\base.py", line 308, in _create_connection
    return _ConnectionRecord(self)
  File "c:\users\richa\onedrive\projects\azurecheckin\venv\lib\site-packages\sqlalchemy\pool\base.py", line 437, in __init__
    self.__connect(first_connect_check=True)
  File "c:\users\richa\onedrive\projects\azurecheckin\venv\lib\site-packages\sqlalchemy\pool\base.py", line 652, in __connect
    connection = pool._invoke_creator(self)
  File "c:\users\richa\onedrive\projects\azurecheckin\venv\lib\site-packages\sqlalchemy\engine\strategies.py", line 114, in connect
    return dialect.connect(*cargs, **cparams)
  File "c:\users\richa\onedrive\projects\azurecheckin\venv\lib\site-packages\sqlalchemy\engine\default.py", line 489, in connect
    return self.dbapi.connect(*cargs, **cparams)
sqlalchemy.exc.ProgrammingError: (pyodbc.ProgrammingError) ('42000', "[42000] [Microsoft][ODBC Driver 17 for SQL Server][SQL Server]Cannot open server 'vwcweb' requested by the login. Client with IP address '73.21.244.163' is not allowed to access the server.  To enable access, use the Windows Azure Management Portal or run sp_set_firewall_rule on the master database to create a firewall rule for this IP address or address range.  It may take up to five minutes for this change to take effect. (40615) (SQLDriverConnect); [42000] [Microsoft][ODBC Driver 17 for SQL Server][SQL Server]Cannot open server 'vwcweb' requested by the login. Client with IP address '73.21.244.163' is not allowed to access the server.  To enable access, use the Windows Azure Management Portal or run sp_set_firewall_rule on the master database to create a firewall rule for this IP address or address range.  It may take up to five minutes for this change to take effect. (40615)")
(Background on this error at: http://sqlalche.me/e/f405)
